Workbook

Sheet matching dist
A1: State | B1: District | C1: Rural/Urban | D1: Match1 | E1: Match2 | H1: District
A2: ANDAMAN & NICOBAR ISLANDS | B2: ANDAMANS | C2: TOTAL | D2: =VLOOKUP(B2,'lgd data'!E:E,1,FALSE) -> #N/A | E2: =VLOOKUP(B2,'lgd data'!F:F,1,FALSE) -> #N/A | H2: ANDAMANS
A3: ANDAMAN & NICOBAR ISLANDS | B3: MIDDLE AND NORTH ANDAMANS | C3: TOTAL | D3: =VLOOKUP(B3,'lgd data'!E:E,1,FALSE) -> #N/A | E3: =VLOOKUP(B3,'lgd data'!F:F,1,FALSE) -> #N/A | H3: MIDDLE AND NORTH ANDAMANS
A4: ANDAMAN & NICOBAR ISLANDS | B4: NICOBARS | C4: TOTAL | D4: =VLOOKUP(B4,'lgd data'!E:E,1,FALSE) -> Nicobars | E4: =VLOOKUP(B4,'lgd data'!F:F,1,FALSE) -> NICOBARS | H4: NICOBARS
A5: ANDHRA PRADESH | B5: ANAKAPALLI | C5: TOTAL | D5: =VLOOKUP(B5,'lgd data'!E:E,1,FALSE) -> Anakapalli | E5: =VLOOKUP(B5,'lgd data'!F:F,1,FALSE) -> Anakapalli | H5: ANAKAPALLI
A6: ANDHRA PRADESH | B6: ANANTAPUR | C6: TOTAL | D6: =VLOOKUP(B6,'lgd data'!E:E,1,FALSE) -> #N/A | E6: =VLOOKUP(B6,'lgd data'!F:F,1,FALSE) -> #N/A | H6: ANANTAPUR
A7: ANDHRA PRADESH | B7: ANNAMAYYA | C7: TOTAL | D7: =VLOOKUP(B7,'lgd data'!E:E,1,FALSE) -> Annamayya | E7: =VLOOKUP(B7,'lgd data'!F:F,1,FALSE) -> Annamayya | H7: ANNAMAYYA
A8: ANDHRA PRADESH | B8: ASR | C8: TOTAL | E8: =VLOOKUP(B8,'lgd data'!F:F,1,FALSE) -> #N/A | H8: ASR
A9: ANDHRA PRADESH | B9: BAPATLA | C9: TOTAL | D9: =VLOOKUP(B9,'lgd data'!E:E,1,FALSE) -> Bapatla | E9: =VLOOKUP(B9,'lgd data'!F:F,1,FALSE) -> Bapatla | H9: BAPATLA
A10: ANDHRA PRADESH | B10: CHITTOOR | C10: TOTAL | D10: =VLOOKUP(B10,'lgd data'!E:E,1,FALSE) -> Chittoor | E10: =VLOOKUP(B10,'lgd data'!F:F,1,FALSE) -> CHITTOOR | H10: CHITTOOR
A11: ANDHRA PRADESH | B11: EAST GODAVARI | C11: TOTAL | D11: =VLOOKUP(B11,'lgd data'!E:E,1,FALSE) -> East Godavari | E11: =VLOOKUP(B11,'lgd data'!F:F,1,FALSE) -> EAST GODAVARI | H11: EAST GODAVARI
A12: ANDHRA PRADESH | B12: ELURU | C12: TOTAL | D12: =VLOOKUP(B12,'lgd data'!E:E,1,FALSE) -> Eluru | E12: =VLOOKUP(B12,'lgd data'!F:F,1,FALSE) -> Eluru | H12: ELURU
A13: ANDHRA PRADESH | B13: GUNTUR | C13: TOTAL | D13: =VLOOKUP(B13,'lgd data'!E:E,1,FALSE) -> Guntur | E13: =VLOOKUP(B13,'lgd data'!F:F,1,FALSE) -> GUNTUR | H13: GUNTUR
A14: ANDHRA PRADESH | B14: KADAPA | C14: TOTAL | D14: =VLOOKUP(B14,'lgd data'!E:E,1,FALSE) -> #N/A | E14: =VLOOKUP(B14,'lgd data'!F:F,1,FALSE) -> #N/A | H14: KADAPA
A15: ANDHRA PRADESH | B15: KAKINADA | C15: TOTAL | D15: =VLOOKUP(B15,'lgd data'!E:E,1,FALSE) -> Kakinada | E15: =VLOOKUP(B15,'lgd data'!F:F,1,FALSE) -> Kakinada | H15: KAKINADA
A16: ANDHRA PRADESH | B16: KONASEEMA | C16: TOTAL | D16: =VLOOKUP(B16,'lgd data'!E:E,1,FALSE) -> #N/A | E16: =VLOOKUP(B16,'lgd data'!F:F,1,FALSE) -> #N/A | H16: KONASEEMA
A17: ANDHRA PRADESH | B17: KRISHNA | C17: TOTAL | D17: =VLOOKUP(B17,'lgd data'!E:E,1,FALSE) -> Krishna | E17: =VLOOKUP(B17,'lgd data'!F:F,1,FALSE) -> KRISHNA | H17: KRISHNA
A18: ANDHRA PRADESH | B18: KURNOOL | C18: TOTAL | D18: =VLOOKUP(B18,'lgd data'!E:E,1,FALSE) -> Kurnool | E18: =VLOOKUP(B18,'lgd data'!F:F,1,FALSE) -> KURNOOL | H18: KURNOOL
A19: ANDHRA PRADESH | B19: MANYAM | C19: TOTAL | D19: =VLOOKUP(B19,'lgd data'!E:E,1,FALSE) -> #N/A | E19: =VLOOKUP(B19,'lgd data'!F:F,1,FALSE) -> #N/A | H19: MANYAM
A20: ANDHRA PRADESH | B20: NANDYAL | C20: TOTAL | D20: =VLOOKUP(B20,'lgd data'!E:E,1,FALSE) -> Nandyal | E20: =VLOOKUP(B20,'lgd data'!F:F,1,FALSE) -> Nandyal | H20: NANDYAL
... A799: WEST BENGAL | B799: UTTAR DINAJPUR | C799: TOTAL | D799: =VLOOKUP(B799,'lgd data'!E:E,1,FALSE) -> Uttar Dinajpur | E799: =VLOOKUP(B799,'lgd data'!F:F,1,FALSE) -> UTTAR DINAJPUR | H799: UTTAR DINAJPUR

Sheet lgd data
A1: S No | B1: State Code | C1: State Name | D1: District LGD Code | E1: District Name (In English) | F1: District Name (In Local language) | G1: Hierarchy | H1: Short Name of District | I1: Census 2001 Code | J1: Census2011 Code | K1: Pesa Status | L1: View Details | M1: View History | N1: View Government Order | O1: View Map
A2: 1 | B2: 35 | C2: Andaman And Nicobar Islands(State) | D2: 603 | E2: Nicobars | F2: NICOBARS | G2: Andaman And Nicobar Islands(State) | H2: NIC | I2: 02 | J2: 638 | K2: Not Covered
A3: 2 | B3: 35 | C3: Andaman And Nicobar Islands(State) | D3: 632 | E3: North And Middle Andaman | F3: NORTH AND MIDDLE ANDAMAN | G3: Andaman And Nicobar Islands(State) | H3: NMA | J3: 639 | K3: Not Covered
A4: 3 | B4: 35 | C4: Andaman And Nicobar Islands(State) | D4: 602 | E4: South Andamans | F4: SOUTH ANDAMANS | G4: Andaman And Nicobar Islands(State) | H4: SAS | I4: 01 | J4: 640 | K4: Not Covered
A5: 4 | B5: 28 | C5: Andhra Pradesh(State) | D5: 745 | E5: Alluri Sitharama Raju | F5: Alluri Sitharama Raju | G5: Andhra Pradesh(State) | H5: LLR | J5: 000 | K5: Not Covered
A6: 5 | B6: 28 | C6: Andhra Pradesh(State) | D6: 744 | E6: Anakapalli | F6: Anakapalli | G6: Andhra Pradesh(State) | H6: NKP | J6: 000 | K6: Not Covered
A7: 6 | B7: 28 | C7: Andhra Pradesh(State) | D7: 502 | E7: Ananthapuramu | F7: అనంతపురము | G7: Andhra Pradesh(State) | H7: ANT | I7: 22 | J7: 553 | K7: Not Covered
A8: 7 | B8: 28 | C8: Andhra Pradesh(State) | D8: 753 | E8: Annamayya | F8: Annamayya | G8: Andhra Pradesh(State) | H8: NNM | J8: 000 | K8: Not Covered
A9: 8 | B9: 28 | C9: Andhra Pradesh(State) | D9: 750 | E9: Bapatla | F9: Bapatla | G9: Andhra Pradesh(State) | H9: BPT | J9: 000 | K9: Not Covered
A10: 9 | B10: 28 | C10: Andhra Pradesh(State) | D10: 503 | E10: Chittoor | F10: CHITTOOR | G10: Andhra Pradesh(State) | H10: CHI | I10: 23 | J10: 554 | K10: Not Covered
A11: 10 | B11: 28 | C11: Andhra Pradesh(State) | D11: 747 | E11: Dr. B.R. Ambedkar Konaseema | F11: డా బి ఆర్ అంబేడ్కర్ కోనసీమ | G11: Andhra Pradesh(State) | H11: KNS | J11: 000 | K11: Not Covered
A12: 11 | B12: 28 | C12: Andhra Pradesh(State) | D12: 505 | E12: East Godavari | F12: EAST GODAVARI | G12: Andhra Pradesh(State) | H12: EGI | I12: 14 | J12: 545 | K12: Not Covered
A13: 12 | B13: 28 | C13: Andhra Pradesh(State) | D13: 748 | E13: Eluru | F13: Eluru | G13: Andhra Pradesh(State) | H13: LR | J13: 000 | K13: Not Covered
A14: 13 | B14: 28 | C14: Andhra Pradesh(State) | D14: 506 | E14: Guntur | F14: GUNTUR | G14: Andhra Pradesh(State) | H14: GNT | I14: 17 | J14: 548 | K14: Not Covered
A15: 14 | B15: 28 | C15: Andhra Pradesh(State) | D15: 746 | E15: Kakinada | F15: Kakinada | G15: Andhra Pradesh(State) | H15: KKN | J15: 000 | K15: Not Covered
A16: 15 | B16: 28 | C16: Andhra Pradesh(State) | D16: 510 | E16: Krishna | F16: KRISHNA | G16: Andhra Pradesh(State) | H16: KRS | I16: 16 | J16: 547 | K16: Not Covered
A17: 16 | B17: 28 | C17: Andhra Pradesh(State) | D17: 511 | E17: Kurnool | F17: KURNOOL | G17: Andhra Pradesh(State) | H17: KUR | I17: 21 | J17: 552 | K17: Not Covered
A18: 17 | B18: 28 | C18: Andhra Pradesh(State) | D18: 755 | E18: Nandyal | F18: Nandyal | G18: Andhra Pradesh(State) | H18: NND | J18: 000 | K18: Not Covered
A19: 18 | B19: 28 | C19: Andhra Pradesh(State) | D19: 749 | E19: Ntr | F19: NTR | G19: Andhra Pradesh(State) | H19: TNR | J19: 000 | K19: Not Covered
A20: 19 | B20: 28 | C20: Andhra Pradesh(State) | D20: 751 | E20: Palnadu | F20: Palnadu | G20: Andhra Pradesh(State) | H20: PLN | J20: 000 | K20: Not Covered
A21: 20 | B21: 28 | C21: Andhra Pradesh(State) | D21: 743 | E21: Parvathipuram Manyam | F21: Parvathipuram Manyam | G21: Andhra Pradesh(State) | H21: PRV | J21: 000 | K21: Not Covered
A22: 21 | B22: 28 | C22: Andhra Pradesh(State) | D22: 517 | E22: Prakasam | F22: PRAKASAM | G22: Andhra Pradesh(State) | H22: PRA | I22: 18 | J22: 549 | K22: Not Covered
A23: 22 | B23: 28 | C23: Andhra Pradesh(State) | D23: 519 | E23: Srikakulam | F23: SRIKAKULAM | G23: Andhra Pradesh(State) | H23: SRK | I23: 11 | J23: 542 | K23: Not Covered
A24: 23 | B24: 28 | C24: Andhra Pradesh(State) | D24: 515 | E24: Sri Potti Sriramulu Nellore | F24: శ్రీ పొట్టి శ్రీరాములు నెల్లూరు | G24: Andhra Pradesh(State) | H24: NEL | I24: 19 | J24: 550 | K24: Not Covered
A25: 24 | B25: 28 | C25: Andhra Pradesh(State) | D25: 754 | E25: Sri Sathya Sai | F25: Sri Sathya Sai | G25: Andhra Pradesh(State) | H25: SSS | J25: 000 | K25: Not Covered
A26: 25 | B26: 28 | C26: Andhra Pradesh(State) | D26: 752 | E26: Tirupati | F26: Tirupati | G26: Andhra Pradesh(State) | H26: TPT | J26: 000 | K26: Not Covered
A27: 26 | B27: 28 | C27: Andhra Pradesh(State) | D27: 520 | E27: Visakhapatnam | F27: విశాఖపట్నం | G27: Andhra Pradesh(State) | H27: VSK | I27: 13 | J27: 544 | K27: Not Covered
A28: 27 | B28: 28 | C28: Andhra Pradesh(State) | D28: 521 | E28: Vizianagaram | F28: VIZIANAGARAM | G28: Andhra Pradesh(State) | H28: VNG | I28: 12 | J28: 543 | K28: Not Covered
A29: 28 | B29: 28 | C29: Andhra Pradesh(State) | D29: 523 | E29: West Godavari | F29: పశ్చిమగోదావరి | G29: Andhra Pradesh(State) | H29: WGI | I29: 15 | J29: 546 | K29: Not Covered
A30: 29 | B30: 28 | C30: Andhra Pradesh(State) | D30: 504 | E30: Y.S.R. Kadapa | F30: వై.ఎస్.ఆర్. కడప | G30: Andhra Pradesh(State) | H30: CUD | I30: 20 | J30: 551 | K30: Not Covered
A31: 30 | B31: 12 | C31: Arunachal Pradesh(State) | D31: 628 | E31: Anjaw | G31: Arunachal Pradesh(State) | H31: ANJ | J31: 260 | K31: Not Covered
A32: 31 | B32: 12 | C32: Arunachal Pradesh(State) | D32: 787 | E32: Bichom | F32: Bichom | G32: Arunachal Pradesh(State) | K32: Not Covered
A33: 32 | B33: 12 | C33: Arunachal Pradesh(State) | D33: 229 | E33: Changlang | F33: CHANGLANG | G33: Arunachal Pradesh(State) | H33: CHG | I33: 12 | J33: 253 | K33: Not Covered
A34: 33 | B34: 12 | C34: Arunachal Pradesh(State) | D34: 230 | E34: Dibang Valley | F34: DIBANG VALLEY | G34: Arunachal Pradesh(State) | H34: DBN | I34: 10 | J34: 257 | K34: Not Covered
A35: 34 | B35: 12 | C35: Arunachal Pradesh(State) | D35: 231 | E35: East Kameng | F35: EAST KAMENG | G35: Arunachal Pradesh(State) | H35: EKG | I35: 03 | J35: 247 | K35: Not Covered
A36: 35 | B36: 12 | C36: Arunachal Pradesh(State) | D36: 232 | E36: East Siang | F36: EAST SIANG | G36: Arunachal Pradesh(State) | H36: ESG | I36: 08 | J36: 251 | K36: Not Covered
A37: 36 | B37: 12 | C37: Arunachal Pradesh(State) | D37: 718 | E37: Kamle | F37: KAMLE | G37: Arunachal Pradesh(State) | H37: KML | J37: 000 | K37: Not Covered
A38: 37 | B38: 12 | C38: Arunachal Pradesh(State) | D38: 786 | E38: Keyi Panyor | F38: Keyi Panyor | G38: Arunachal Pradesh(State) | K38: Not Covered
A39: 38 | B39: 12 | C39: Arunachal Pradesh(State) | D39: 677 | E39: Kra Daadi | F39: KRA DAADI | G39: Arunachal Pradesh(State) | H39: KRD | J39: 000 | K39: Not Covered
A40: 39 | B40: 12 | C40: Arunachal Pradesh(State) | D40: 233 | E40: Kurung Kumey | F40: KURUNG KUMEY | G40: Arunachal Pradesh(State) | H40: KKY | I40: 14 | J40: 256 | K40: Not Covered
...

Sheet udise data
A1: State | B1: District
A2: ANDAMAN & NICOBAR ISLANDS | B2: ANDAMANS
A3: ANDAMAN & NICOBAR ISLANDS | B3: MIDDLE AND NORTH ANDAMANS
A4: ANDAMAN & NICOBAR ISLANDS | B4: NICOBARS
A5: ANDAMAN & NICOBAR ISLANDS | B5: STATE TOTAL
A6: ANDHRA PRADESH | B6: ANAKAPALLI
A7: ANDHRA PRADESH | B7: ANANTAPUR
A8: ANDHRA PRADESH | B8: ANNAMAYYA
A9: ANDHRA PRADESH | B9: ASR
A10: ANDHRA PRADESH | B10: BAPATLA
A11: ANDHRA PRADESH | B11: CHITTOOR
A12: ANDHRA PRADESH | B12: EAST GODAVARI
... A835: WEST BENGAL | B835: UTTAR DINAJPUR

Sheet changes be made
A2: State | B2: District | C2: Remarks
A3: ANDAMAN & NICOBAR ISLANDS | B3: South Andamans
A4: ANDAMAN & NICOBAR ISLANDS | B4: North And Middle Andaman
A5: ANDHRA PRADESH | B5: Ananthapuramu
A6: ANDHRA PRADESH | B6: Y.S.R. Kadapa
A7: ANDHRA PRADESH | B7: Dr. B.R. Ambedkar Konaseema
A8: ANDHRA PRADESH | B8: Parvathipuram Manyam
A9: ANDHRA PRADESH | B9: Sri Potti Sriramulu Nellore
A10: ANDHRA PRADESH | B10: Sri Sathya Sai
A11: ARUNACHAL PRADESH | B11: CAPITAL COMPLEX ITANAGAR | C11: (Administrative Div) located in Papum pare | D11: Merge with Papum Pare
A12: ARUNACHAL PRADESH | B12: Kra Daadi
A13: ARUNACHAL PRADESH | B13: Leparada
A14: ASSAM | B14: Kamrup Metro
A15: ASSAM | B15: Kamrup
A16: ASSAM | B16: Sribhumi
A17: ASSAM | B17: Marigaon
A18: ASSAM | B18: Sivasagar
A19: ASSAM | B19: South Salmara Mancachar
A20: BIHAR | B20: Aurangabad(Bihar)
A21: BIHAR | B21: Purbi Champaran
A22: CHHATTISGARH | B22: Balodabazar-Bhatapara
A23: CHHATTISGARH | B23: Bastar
... A36: DADRA & NAGAR HAVELI AND DAMAN & DIU | B36: Diu
A37: DELHI | B37: NORTH EAST I | C37: Sub Division of Delhi | D37: Merge with North East District
A38: DELHI | B38: NORTH EAST II | C38: Sub Division of Delhi | D38: Merge with North East District
A39: DELHI | B39: NORTH WEST A | C39: Sub Division of Delhi | D39: Merge all North Wests and rename to North West
A40: DELHI | B40: NORTH WEST B | C40: Sub Division of Delhi | D40: Merge all North Wests and rename to North West
A41: DELHI | B41: NORTH WEST B-I | C41: Sub Division of Delhi | D41: Merge all North Wests and rename to North West
A42: DELHI | B42: NORTH WEST B-II | C42: Sub Division of Delhi | D42: Merge all North Wests and rename to North West
A43: DELHI | B43: SOUTH WEST A | C43: Sub Division of Delhi | D43: Merge all South Wests and rename to South West
A44: DELHI | B44: SOUTH WEST B | C44: Sub Division of Delhi | D44: Merge all South Wests and rename to South West
A45: DELHI | B45: SOUTH WEST B-I | C45: Sub Division of Delhi | D45: Merge all South Wests and rename to South West
A46: DELHI | B46: SOUTH WEST B-II | C46: Sub Division of Delhi | D46: Merge all South Wests and rename to South West
A47: DELHI | B47: WEST A | C47: Sub Division of Delhi | D47: Merge all Wests and rename to West
A48: DELHI | B48: WEST B | C48: Sub Division of Delhi | D48: Merge all Wests and rename to West
A49: GUJARAT | B49: Arvalli
A50: GUJARAT | B50: Devbhumi Dwarka
A51: GUJARAT | B51: Dahod
A52: GUJARAT | B52: Dangs
A53: HIMACHAL PRADESH | B53: Bilaspur (H.P.)
...

Sheet Sheet1
A1: State Name | B1: State | C1: Districts to be merged | D1: District Name (In English) | E1: Merged Name be given | H1: Renamed
A2: Arunachal Pradesh(State) | B2: ARUNACHAL PRADESH | C2: CAPITAL COMPLEX ITANAGAR | D2: {=PROPER(TRIM(C2:C155))} -> Capital Complex Itanagar | E2: Papum pare
A3: Arunachal Pradesh(State) | B3: ARUNACHAL PRADESH | C3: Papum pare | D3: Papum Pare | E3: Papum pare
A5: Assam(State) | B5: ASSAM | C5: KAMRUP-RURAL | D5: Kamrup-Rural | H5: Kamrup
A6: Assam(State) | B6: ASSAM | C6: KARIMGANJ | D6: Karimganj | H6: Sribhumi
A7: Assam(State) | B7: ASSAM | C7: SIBSAGAR | D7: Sibsagar | H7: Sivasagar
A9: Chhattisgarh(State) | B9: CHHATTISGARH | C9: BALODABAZAR | D9: Balodabazar | H9: Balodabazar-Bhatapara
A10: Chhattisgarh(State) | B10: CHHATTISGARH | C10: BALRAMPUR | D10: Balrampur | H10: Balrampur-Ramanujganj
A11: Chhattisgarh(State) | B11: CHHATTISGARH | C11: DANTEWADA | D11: Dantewada | H11: Dakshin Bastar Dantewada
A12: Chhattisgarh(State) | B12: CHHATTISGARH | C12: GOURELA PENDRA MARVAHI | D12: Gourela Pendra Marvahi | H12: Gaurela-Pendra-Marwahi
A13: Chhattisgarh(State) | B13: CHHATTISGARH | C13: MOHLA-MANPUR-CHOWKI | D13: Mohla-Manpur-Chowki | H13: Mohla-Manpur-Ambagarh Chouki
A14: Chhattisgarh(State) | B14: CHHATTISGARH | C14: KANKER | D14: Kanker | H14: Uttar Bastar Kanker
A15: Chhattisgarh(State) | B15: CHHATTISGARH | C15: KORIYA | D15: Koriya | H15: Korea
A16: Chhattisgarh(State) | B16: CHHATTISGARH | C16: KAWARDHA | D16: Kawardha | H16: Kabeerdham
A18: Gujarat(State) | B18: GUJARAT | C18: DEVBHOOMI DWARKA | D18: Devbhoomi Dwarka | H18: Devbhumi Dwarka
... A29: Jharkhand(State) | B29: JHARKHAND | C29: PASHCHIMI SINGHBHUM | D29: Pashchimi Singhbhum | H29: West Singhbhum
A31: Delhi(State) | B31: DELHI | C31: NORTH EAST | D31: North East | E31: North East
A32: Delhi(State) | B32: DELHI | C32: NORTH EAST I | D32: North East I | E32: North East
A33: Delhi(State) | B33: DELHI | C33: NORTH EAST II | D33: North East Ii | E33: North East
A34: Delhi(State) | B34: DELHI | C34: NORTH WEST A | D34: North West A | E34: North West
A35: Delhi(State) | B35: DELHI | C35: NORTH WEST B | D35: North West B | E35: North West
A36: Delhi(State) | B36: DELHI | C36: NORTH WEST B-I | D36: North West B-I | E36: North West
A37: Delhi(State) | B37: DELHI | C37: NORTH WEST B-II | D37: North West B-Ii | E37: North West
A38: Delhi(State) | B38: DELHI | C38: SOUTH WEST A | D38: South West A | E38: South West
A39: Delhi(State) | B39: DELHI | C39: SOUTH WEST B | D39: South West B | E39: South West
A40: Delhi(State) | B40: DELHI | C40: SOUTH WEST B-I | D40: South West B-I | E40: South West
A41: Delhi(State) | B41: DELHI | C41: SOUTH WEST B-II | D41: South West B-Ii | E41: South West
A42: Delhi(State) | B42: DELHI | C42: WEST A | D42: West A | E42: West
... A53: Karnataka(State) | B53: KARNATAKA | C53: UTTARA KANNADA SIRSI | D53: Uttara Kannada Sirsi | E53: Uttara Kannada
A54: Karnataka(State) | B54: KARNATAKA | C54: RAMANAGARA | D54: Ramanagara | H54: Bengaluru South
A55: Karnataka(State) | B55: KARNATAKA | C55: BAGALKOT | D55: Bagalkot | H55: Bagalkote
A56: Karnataka(State) | B56: KARNATAKA | C56: CHAMARAJANAGARA | D56: Chamarajanagara | H56: Chamarajanagar
A57: Karnataka(State) | B57: KARNATAKA | C57: CHIKKAMANGALURU | D57: Chikkamangaluru | H57: Chikkamagaluru
A58: Karnataka(State) | B58: KARNATAKA | C58: KALBURGI | D58: Kalburgi | H58: Kalaburagi
A59: Karnataka(State) | B59: KARNATAKA | C59: YADAGIRI | D59: Yadagiri | H59: Yadgir
A61: Lakshadweep(State) | B61: LAKSHADWEEP | C61: LAKSHADWEEP | D61: Lakshadweep | H61: Lakshadweep District
A63: Madhya Pradesh(State) | B63: MADHYA PRADESH
A64: Madhya Pradesh(State) | B64: MADHYA PRADESH | C64: HOSHANGABAD | D64: Hoshangabad | H64: Narmadapuram
A65: Madhya Pradesh(State) | B65: MADHYA PRADESH | C65: KHANDWA | D65: Khandwa | H65: Khandwa (East Nimar)
A66: Madhya Pradesh(State) | B66: MADHYA PRADESH | C66: KHARGONE | D66: Khargone | H66: Khargone (West Nimar)
...
